Workbook
Name mutual_fund: 'data valadiation'!$C$4

Sheet nifty 500 co list
B1: LTP (₹) | C1: 1D change % | D1: Market Cap (Cr) | E1: 52W High / Low (₹) | I1: Volume | J1: Company | L1: High | M1: Low | N1: Current Price
B2: 486.95 | C2: 8.07 | D2: 9832 | E2: 691.80/343.50 | I2: 2551655 | J2: Balrampur Chini Mills Ltd. | L2: 691.8 | M2: 343.5 | N2: 486.95
B3: 714.6 | C3: 5.6 | D3: 19023 | E3: 1,313.25/648.60 | I3: 4096631 | J3: KEC International Ltd. | L3: 1313.25 | M3: 648.6 | N3: 714.6
B4: 4014.4 | C4: 5.37 | D4: 54345 | E4: 6,133.40/1,941.05 | I4: 6327755 | J4: BSE Ltd. | L4: 6133.4 | M4: 1941.05 | N4: 4014.4
B5: 229.31 | C5: 4.57 | D5: 31797 | E5: 311.80/186.03 | I5: 10632915 | J5: NLC India Ltd. | L5: 311.8 | M5: 186.03 | N5: 229.31
B6: 684.7 | C6: 4.38 | D6: 53342 | E6: 1,576.35/606.00 | I6: 108682122 | J6: IndusInd Bank Ltd. | L6: 1576.35 | M6: 606 | N6: 684.7
B7: 549.7 | C7: 4.32 | D7: 21996 | E7: 674.30/350.00 | I7: 888471 | J7: Krishna Institute of Medical Sciences Ltd. | L7: 674.3 | M7: 350 | N7: 549.7
B8: 5436.45 | C8: 4.02 | D8: 28266 | E8: 8,480.00/2,805.55 | I8: 122692 | J8: Godfrey Phillips India Ltd. | L8: 8480 | M8: 2805.55 | N8: 5436.45
B9: 4658.4 | C9: 3.94 | D9: 51757 | E9: 5,535.85/3,622.25 | I9: 182032 | J9: Sundaram Finance Ltd. | L9: 5535.85 | M9: 3622.25 | N9: 4658.4
B10: 225.53 | C10: 3.66 | D10: 143286 | E10: 394.70/198.65 | I10: 28455086 | J10: Jio Financial Services Ltd. | L10: 394.7 | M10: 198.65 | N10: 225.53
B11: 853.45 | C11: 3.55 | D11: 135189 | E11: 2,174.10/758.00 | I11: 4826264 | J11: Adani Green Energy Ltd. | L11: 2174.1 | M11: 758 | N11: 853.45
B12: 357.65 | C12: 3.37 | D12: 23025 | E12: 484.00/261.25 | I12: 3496657 | J12: Crompton Greaves Consumer Electricals Ltd. | L12: 484 | M12: 261.25 | N12: 357.65
B13: 735.75 | C13: 3.36 | D13: 25825 | E13: 1,037.00/357.05 | I13: 1805402 | J13: Aegis Logistics Ltd. | L13: 1037 | M13: 357.05 | N13: 735.75
... B501: 522.55 | C501: -9.52 | D501: 12503 | E501: 736.30/452.00 | I501: 2913334 | J501: Indegene Ltd. | L501: 736.3 | M501: 452 | N501: 522.55

Sheet return on incides
A1: Symbol | B1: 1M | C1: 3M | D1: 1Yr | E1: 3Yr | F1: 5Yr | G1: 10Yr | Q1: mutual funds: kotak | Z1: kotak & nifty indices | AE1: nippon & nifty indices | AJ1: parag & nifty indices | AO1: quant & nifty indices
A2: Nifty 50 | B2: -3.88 | C2: -8.52 | D2: 1.09 | E2: 11.94 | F2: 17.92 | G2: 11.29 | I2: Row Labels | J2: Sum of 1M | K2: Sum of 3M | L2: Sum of 1Yr | M2: Sum of 3Yr | N2: Sum of 5Yr | O2: Sum of 10Yr | Q2: Period Invested for | R2: 1 Month | S2: 3 Month | T2: 1 Year | U2: 3 Year | V2: 5 Year | W2: 10 Year | X2: sprklines | Z2: 1 yr | AA2: 3yr | AB2: 5yr | AC2: 10yr | AD2: kotak is performing beter than these indices | AE2: 1 yr | AF2: 3yr | AG2: 5yr | AH2: 10yr | AJ2: 1 yr | AK2: 3yr | AL2: 5yr | AM2: 10yr | AO2: 1 yr | AP2: 3yr | AQ2: 5yr | AR2: 10yr
A3: Nifty 100 | B3: -4.15 | C3: -10.38 | D3: 0.49 | E3: 12.01 | F3: 17.99 | G3: 11.47 | I3: Nifty 500 | J3: -5.11 | K3: -12.91 | L3: 0.14 | M3: 13.75 | N3: 19.85 | O3: 12.24 | Q3: =HYPERLINK("#'Kotak Holdings'!A1", " Kotak returns") -> Kotak returns | R3: -0.0774 | S3: -0.1864 | T3: 0.083 | U3: 0.6441 | V3: 1.875 | W3: 3.2846 | Z3: =IF($T$3>D2,"good","not good") -> not good | AA3: =IF($U$3>E2,"good","not good") -> not good | AB3: =IF($W$3>F2,"good","not good") -> not good | AC3: =IF($V$3>G2,"good","not good") -> not good | AD3: =IF(Z3="good",A2,"") | AE3: =IF($T$4>D2,"good") -> FALSE | AF3: =IF($U$4>E2,"good") -> FALSE | AG3: =IF($V$4>F2,"good") -> FALSE | AH3: =IF($W$4>G2,"good") -> FALSE | AK3: =IF($U$5>E2,"good") -> FALSE | AL3: =IF($V$5>F2,"good") -> FALSE | AM3: =IF($W$5>G2,"good") -> FALSE | AO3: =IF($T$6>D2,"good") -> FALSE | AP3: =IF($U$6>E2,"good") -> FALSE | AQ3: =IF($V$6>F2,"good") -> FALSE | AR3: =IF($W$6>G2,"good") -> FALSE
A4: Nifty 200 | B4: -4.72 | C4: -11.7 | D4: 0.26 | E4: 13.2 | F4: 19.07 | G4: 11.87 | I4: Grand Total | J4: -5.11 | K4: -12.91 | L4: 0.14 | M4: 13.75 | N4: 19.85 | O4: 12.24 | Q4: =HYPERLINK("#'nippon holdings'!A1", "nippon returns") -> nippon returns | R4: -0.0721 | S4: -0.21 | T4: 0.0108 | U4: 0.7864 | V4: 2.9546 | W4: 4.8163 | Z4: =IF($T$3>D3,"good","not good") -> not good | AA4: =IF($U$3>E3,"good","not good") -> not good | AB4: =IF($V$3>F3,"good","not good") -> not good | AC4: =IF($V$3>G3,"good","not good") -> not good | AD4: =IF(Z4="good",A3,"") | AE4: =IF($T$4>D3,"good") -> FALSE | AF4: =IF($U$4>E3,"good") -> FALSE | AG4: =IF($V$4>F3,"good") -> FALSE | AH4: =IF($W$4>G3,"good") -> FALSE | AJ4: =IF($T$5>D3,"good") -> FALSE | AK4: =IF($U$5>E3,"good") -> FALSE | AL4: =IF($V$5>F3,"good") -> FALSE | AM4: =IF($W$5>G3,"good") -> FALSE | AO4: =IF($T$6>D3,"good") -> FALSE | AP4: =IF($U$6>E3,"good") -> FALSE | AQ4: =IF($V$6>F3,"good") -> FALSE | AR4: =IF($W$6>G3,"good") -> FALSE
A5: Nifty 500 | B5: -5.11 | C5: -12.91 | D5: 0.14 | E5: 13.75 | F5: 19.85 | G5: 12.24 | Q5: =HYPERLINK("#'parag holdings'!A1","parag parik returns") -> parag parik returns | R5: -0.0356 | S5: -0.0595 | T5: 0.1028 | U5: 0.6472 | V5: 2.0871 | W5: 3.6719 | Z5: =IF($T$3>D4,"good","not good") -> not good | AA5: =IF($U$3>E4,"good","not good") -> not good | AB5: =IF($V$3>F4,"good","not good") -> not good | AC5: =IF($V$3>G4,"good","not good") -> not good | AD5: =IF(Z5="good",A4,"") | AE5: =IF($T$4>D4,"good") -> FALSE | AF5: =IF($U$4>E4,"good") -> FALSE | AG5: =IF($V$4>F4,"good") -> FALSE | AH5: =IF($W$4>G4,"good") -> FALSE | AJ5: =IF($T$5>D4,"good") -> FALSE | AK5: =IF($U$5>E4,"good") -> FALSE | AL5: =IF($V$5>F4,"good") -> FALSE | AM5: =IF($W$5>G4,"good") -> FALSE | AO5: =IF($T$6>D4,"good") -> FALSE | AP5: =IF($U$6>E4,"good") -> FALSE | AQ5: =IF($V$6>F4,"good") -> FALSE | AR5: =IF($W$6>G4,"good") -> FALSE
A6: NIFTY TOTAL MKT | B6: -5.27 | C6: -13.3 | D6: 0.22 | E6: 14.14 | F6: 20.3 | G6: 12.46 | Q6: =HYPERLINK("#'quant holdings'!A1", "quant returns") -> quant returns | R6: -0.0587 | S6: -0.1521 | T6: -0.0988 | U6: 0.6834 | V6: 2.6856 | W6: 3.3162 | Z6: =IF($T$3>D5,"good","not good") -> not good | AA6: =IF($U$3>E5,"good","not good") -> not good | AB6: =IF($V$3>F5,"good","not good") -> not good | AC6: =IF($V$3>G5,"good","not good") -> not good | AD6: =IF(Z6="good",A5,"") | AE6: =IF($T$4>D5,"good") -> FALSE | AF6: =IF($U$4>E5,"good") -> FALSE | AG6: =IF($V$4>F5,"good") -> FALSE | AH6: =IF($W$4>G5,"good") -> FALSE | AJ6: =IF($T$5>D5,"good") -> FALSE | AK6: =IF($U$5>E5,"good") -> FALSE | AL6: =IF($V$5>F5,"good") -> FALSE | AM6: =IF($W$5>G5,"good") -> FALSE | AO6: =IF($T$6>D5,"good") -> FALSE | AP6: =IF($U$6>E5,"good") -> FALSE | AQ6: =IF($V$6>F5,"good") -> FALSE | AR6: =IF($W$6>G5,"good") -> FALSE
A7: Nifty Next 50 | B7: -5.39 | C7: -19.15 | D7: -1.53 | E7: 14.77 | F7: 19.53 | G7: 12.76 | Z7: =IF($T$3>D6,"good","not good") -> not good | AA7: =IF($U$3>E6,"good","not good") -> not good | AB7: =IF($V$3>F6,"good","not good") -> not good | AC7: =IF($V$3>G6,"good","not good") -> not good | AD7: =IF(Z7="good",A6,"") | AE7: =IF($T$4>D6,"good") -> FALSE | AF7: =IF($U$4>E6,"good") -> FALSE | AG7: =IF($V$4>F6,"good") -> FALSE | AH7: =IF($W$4>G6,"good") -> FALSE | AJ7: =IF($T$5>D6,"good") -> FALSE | AK7: =IF($U$5>E6,"good") -> FALSE | AL7: =IF($V$5>F6,"good") -> FALSE | AM7: =IF($W$5>G6,"good") -> FALSE | AO7: =IF($T$6>D6,"good") -> FALSE | AP7: =IF($U$6>E6,"good") -> FALSE | AQ7: =IF($V$6>F6,"good") -> FALSE | AR7: =IF($W$6>G6,"good") -> FALSE
A8: NIFTY Smallcap 100 | B8: -8.68 | C8: -22.31 | D8: -2.56 | E8: 15.63 | F8: 25.16 | G8: 11.39 | Z8: =IF($T$3>D7,"good","not good") -> good | AA8: =IF($U$3>E7,"good","not good") -> not good | AB8: =IF($V$3>F7,"good","not good") -> not good | AC8: =IF($V$3>G7,"good","not good") -> not good | AD8: =IF(Z8="good",A7,"") -> Nifty Next 50 | AE8: =IF($T$4>D7,"good") -> good | AF8: =IF($U$4>E7,"good") -> FALSE | AG8: =IF($V$4>F7,"good") -> FALSE | AH8: =IF($W$4>G7,"good") -> FALSE | AJ8: =IF($T$5>D7,"good") -> good | AK8: =IF($U$5>E7,"good") -> FALSE | AL8: =IF($V$5>F7,"good") -> FALSE | AM8: =IF($W$5>G7,"good") -> FALSE | AO8: =IF($T$6>D7,"good") -> good | AP8: =IF($U$6>E7,"good") -> FALSE | AQ8: =IF($V$6>F7,"good") -> FALSE | AR8: =IF($W$6>G7,"good") -> FALSE
A9: NIFTY500 MULTICAP 50:25:25 | B9: -5.93 | C9: -15.08 | D9: 0.02 | E9: 15.65 | F9: 22.54 | G9: 13.32 | Z9: =IF($T$3>D8,"good","not good") -> good | AA9: =IF($U$3>E8,"good","not good") -> not good | AB9: =IF($V$3>F8,"good","not good") -> not good | AC9: =IF($V$3>G8,"good","not good") -> not good | AD9: =IF(Z9="good",A8,"") -> NIFTY Smallcap 100 | AE9: =IF($T$4>D8,"good") -> good | AF9: =IF($U$4>E8,"good") -> FALSE | AG9: =IF($V$4>F8,"good") -> FALSE | AH9: =IF($W$4>G8,"good") -> FALSE | AJ9: =IF($T$5>D8,"good") -> good | AK9: =IF($U$5>E8,"good") -> FALSE | AL9: =IF($V$5>F8,"good") -> FALSE | AM9: =IF($W$5>G8,"good") -> FALSE | AO9: =IF($T$6>D8,"good") -> good | AP9: =IF($U$6>E8,"good") -> FALSE | AQ9: =IF($V$6>F8,"good") -> FALSE | AR9: =IF($W$6>G8,"good") -> FALSE
A10: NIFTY LargeMidcap 250 | B10: -5.55 | C10: -13.79 | D10: 0.79 | E10: 16.27 | F10: 22.12 | G10: 13.9 | Z10: =IF($T$3>D9,"good","not good") -> good | AA10: =IF($U$3>E9,"good","not good") -> not good | AB10: =IF($V$3>F9,"good","not good") -> not good | AC10: =IF($V$3>G9,"good","not good") -> not good | AD10: =IF(Z10="good",A9,"") -> NIFTY500 MULTICAP 50:25:25 | AE10: =IF($T$4>D9,"good") -> FALSE | AF10: =IF($U$4>E9,"good") -> FALSE | AG10: =IF($V$4>F9,"good") -> FALSE | AH10: =IF($W$4>G9,"good") -> FALSE | AJ10: =IF($T$5>D9,"good") -> good | AK10: =IF($U$5>E9,"good") -> FALSE | AL10: =IF($V$5>F9,"good") -> FALSE | AM10: =IF($W$5>G9,"good") -> FALSE | AO10: =IF($T$6>D9,"good") -> FALSE | AP10: =IF($U$6>E9,"good") -> FALSE | AQ10: =IF($V$6>F9,"good") -> FALSE | AR10: =IF($W$6>G9,"good") -> FALSE
A11: Nifty500 LargeMidSmall Equal-Cap Weighted | B11: -6.56 | C11: -16.65 | D11: -0.24 | E11: 16.77 | F11: 23.92 | G11: 13.81 | Z11: =IF($T$3>D10,"good","not good") -> not good | AA11: =IF($U$3>E10,"good","not good") -> not good | AB11: =IF($V$3>F10,"good","not good") -> not good | AC11: =IF($V$3>G10,"good","not good") -> not good | AD11: =IF(Z11="good",A10,"") | AE11: =IF($T$4>D10,"good") -> FALSE | AF11: =IF($U$4>E10,"good") -> FALSE | AG11: =IF($V$4>F10,"good") -> FALSE | AH11: =IF($W$4>G10,"good") -> FALSE | AJ11: =IF($T$5>D10,"good") -> FALSE | AK11: =IF($U$5>E10,"good") -> FALSE | AL11: =IF($V$5>F10,"good") -> FALSE | AM11: =IF($W$5>G10,"good") -> FALSE | AO11: =IF($T$6>D10,"good") -> FALSE | AP11: =IF($U$6>E10,"good") -> FALSE | AQ11: =IF($V$6>F10,"good") -> FALSE | AR11: =IF($W$6>G10,"good") -> FALSE
A12: NIFTY SMALLCAP 50 | B12: -8.67 | C12: -22.39 | D12: 1.99 | E12: 17.14 | F12: 25.55 | G12: 9.76 | Z12: =IF($T$3>D11,"good","not good") -> good | AA12: =IF($U$3>E11,"good","not good") -> not good | AB12: =IF($V$3>F11,"good","not good") -> not good | AC12: =IF($V$3>G11,"good","not good") -> not good | AD12: =IF(Z12="good",A11,"") -> Nifty500 LargeMidSmall Equal-Cap Weighted | AE12: =IF($T$4>D11,"good") -> good | AF12: =IF($U$4>E11,"good") -> FALSE | AG12: =IF($V$4>F11,"good") -> FALSE | AH12: =IF($W$4>G11,"good") -> FALSE | AJ12: =IF($T$5>D11,"good") -> good | AK12: =IF($U$5>E11,"good") -> FALSE | AL12: =IF($V$5>F11,"good") -> FALSE | AM12: =IF($W$5>G11,"good") -> FALSE | AO12: =IF($T$6>D11,"good") -> good | AP12: =IF($U$6>E11,"good") -> FALSE | AQ12: =IF($V$6>F11,"good") -> FALSE | AR12: =IF($W$6>G11,"good") -> FALSE
A13: Nifty smallcap 250 | B13: -8.69 | C13: -22.29 | D13: -2.66 | E13: 17.51 | F13: 27.4 | G13: 13.52 | Z13: =IF($T$3>D12,"good","not good") -> not good | AA13: =IF($U$3>E12,"good","not good") -> not good | AB13: =IF($V$3>F12,"good","not good") -> not good | AC13: =IF($V$3>G12,"good","not good") -> not good | AD13: =IF(Z13="good",A12,"") | AE13: =IF($T$4>D12,"good") -> FALSE | AF13: =IF($U$4>E12,"good") -> FALSE | AG13: =IF($V$4>F12,"good") -> FALSE | AH13: =IF($W$4>G12,"good") -> FALSE | AJ13: =IF($T$5>D12,"good") -> FALSE | AK13: =IF($U$5>E12,"good") -> FALSE | AL13: =IF($V$5>F12,"good") -> FALSE | AM13: =IF($W$5>G12,"good") -> FALSE | AO13: =IF($T$6>D12,"good") -> FALSE | AP13: =IF($U$6>E12,"good") -> FALSE | AQ13: =IF($V$6>F12,"good") -> FALSE | AR13: =IF($W$6>G12,"good") -> FALSE
A14: NIFTY MID SELECT | B14: -7.04 | C14: -16.2 | D14: 1.2 | E14: 17.53 | F14: 24.1 | G14: 15.29 | Z14: =IF($T$3>D13,"good","not good") -> good | AA14: =IF($U$3>E13,"good","not good") -> not good | AB14: =IF($V$3>F13,"good","not good") -> not good | AC14: =IF($V$3>G13,"good","not good") -> not good | AD14: =IF(Z14="good",A13,"") -> Nifty smallcap 250 | AE14: =IF($T$4>D13,"good") -> good | AF14: =IF($U$4>E13,"good") -> FALSE | AG14: =IF($V$4>F13,"good") -> FALSE | AH14: =IF($W$4>G13,"good") -> FALSE | AJ14: =IF($T$5>D13,"good") -> good | AK14: =IF($U$5>E13,"good") -> FALSE | AL14: =IF($V$5>F13,"good") -> FALSE | AM14: =IF($W$5>G13,"good") -> FALSE | AO14: =IF($T$6>D13,"good") -> good | AP14: =IF($U$6>E13,"good") -> FALSE | AQ14: =IF($V$6>F13,"good") -> FALSE | AR14: =IF($W$6>G13,"good") -> FALSE
A15: Nifty MidSmallcap 400 | B15: -7.62 | C15: -19.09 | D15: -0.49 | E15: 19.47 | F15: 26.49 | G15: 15.28 | Z15: =IF($T$3>D14,"good","not good") -> not good | AA15: =IF($U$3>E14,"good","not good") -> not good | AB15: =IF($V$3>F14,"good","not good") -> not good | AC15: =IF($V$3>G14,"good","not good") -> not good | AD15: =IF(Z15="good",A14,"") | AE15: =IF($T$4>D14,"good") -> FALSE | AF15: =IF($U$4>E14,"good") -> FALSE | AG15: =IF($V$4>F14,"good") -> FALSE | AH15: =IF($W$4>G14,"good") -> FALSE | AJ15: =IF($T$5>D14,"good") -> FALSE | AK15: =IF($U$5>E14,"good") -> FALSE | AL15: =IF($V$5>F14,"good") -> FALSE | AM15: =IF($W$5>G14,"good") -> FALSE | AO15: =IF($T$6>D14,"good") -> FALSE | AP15: =IF($U$6>E14,"good") -> FALSE | AQ15: =IF($V$6>F14,"good") -> FALSE | AR15: =IF($W$6>G14,"good") -> FALSE
A16: Nifty Midcap 150 | B16: -7.03 | C16: -17.24 | D16: 0.73 | E16: 20.35 | F16: 26.09 | G16: 16.13 | Z16: =IF($T$3>D15,"good","not good") -> good | AA16: =IF($U$3>E15,"good","not good") -> not good | AB16: =IF($V$3>F15,"good","not good") -> not good | AC16: =IF($V$3>G15,"good","not good") -> not good | AD16: =IF(Z16="good",A15,"") -> Nifty MidSmallcap 400 | AE16: =IF($T$4>D15,"good") -> good | AF16: =IF($U$4>E15,"good") -> FALSE | AG16: =IF($V$4>F15,"good") -> FALSE | AH16: =IF($W$4>G15,"good") -> FALSE | AJ16: =IF($T$5>D15,"good") -> good | AK16: =IF($U$5>E15,"good") -> FALSE | AL16: =IF($V$5>F15,"good") -> FALSE | AM16: =IF($W$5>G15,"good") -> FALSE | AO16: =IF($T$6>D15,"good") -> good | AP16: =IF($U$6>E15,"good") -> FALSE | AQ16: =IF($V$6>F15,"good") -> FALSE | AR16: =IF($W$6>G15,"good") -> FALSE
A17: NIFTY MIDCAP 100 | B17: -7.62 | C17: -18 | D17: -0.56 | E17: 20.81 | F17: 26.38 | G17: 15 | Z17: =IF($T$3>D16,"good","not good") -> not good | AA17: =IF($U$3>E16,"good","not good") -> not good | AB17: =IF($V$3>F16,"good","not good") -> not good | AC17: =IF($V$3>G16,"good","not good") -> not good | AD17: =IF(Z17="good",A16,"") | AE17: =IF($T$4>D16,"good") -> FALSE | AF17: =IF($U$4>E16,"good") -> FALSE | AG17: =IF($V$4>F16,"good") -> FALSE | AH17: =IF($W$4>G16,"good") -> FALSE | AJ17: =IF($T$5>D16,"good") -> FALSE | AK17: =IF($U$5>E16,"good") -> FALSE | AL17: =IF($V$5>F16,"good") -> FALSE | AM17: =IF($W$5>G16,"good") -> FALSE | AO17: =IF($T$6>D16,"good") -> FALSE | AP17: =IF($U$6>E16,"good") -> FALSE | AQ17: =IF($V$6>F16,"good") -> FALSE | AR17: =IF($W$6>G16,"good") -> FALSE
A18: Nifty Midcap 50 | B18: -6.52 | C18: -16.77 | D18: -1.26 | E18: 22 | F18: 28.12 | G18: 16.01 | Z18: =IF($T$3>D17,"good","not good") -> good | AA18: =IF($U$3>E17,"good","not good") -> not good | AB18: =IF($V$3>F17,"good","not good") -> not good | AC18: =IF($V$3>G17,"good","not good") -> not good | AD18: =IF(Z18="good",A17,"") -> NIFTY MIDCAP 100 | AE18: =IF($T$4>D17,"good") -> good | AF18: =IF($U$4>E17,"good") -> FALSE | AG18: =IF($V$4>F17,"good") -> FALSE | AH18: =IF($W$4>G17,"good") -> FALSE | AJ18: =IF($T$5>D17,"good") -> good | AK18: =IF($U$5>E17,"good") -> FALSE | AL18: =IF($V$5>F17,"good") -> FALSE | AM18: =IF($W$5>G17,"good") -> FALSE | AO18: =IF($T$6>D17,"good") -> good | AP18: =IF($U$6>E17,"good") -> FALSE | AQ18: =IF($V$6>F17,"good") -> FALSE | AR18: =IF($W$6>G17,"good") -> FALSE
A19: NIFTY MICROCAP250 | B19: -9.4 | C19: -22.89 | D19: 3.04 | E19: 28.3 | F19: 41.9 | G19: 19.54 | Z19: =IF($T$3>D18,"good","not good") -> good | AA19: =IF($U$3>E18,"good","not good") -> not good | AB19: =IF($V$3>F18,"good","not good") -> not good | AC19: =IF($V$3>G18,"good","not good") -> not good | AD19: =IF(Z19="good",A18,"") -> Nifty Midcap 50 | AE19: =IF($T$4>D18,"good") -> good | AF19: =IF($U$4>E18,"good") -> FALSE | AG19: =IF($V$4>F18,"good") -> FALSE | AH19: =IF($W$4>G18,"good") -> FALSE | AJ19: =IF($T$5>D18,"good") -> good | AK19: =IF($U$5>E18,"good") -> FALSE | AL19: =IF($V$5>F18,"good") -> FALSE | AM19: =IF($W$5>G18,"good") -> FALSE | AO19: =IF($T$6>D18,"good") -> good | AP19: =IF($U$6>E18,"good") -> FALSE | AQ19: =IF($V$6>F18,"good") -> FALSE | AR19: =IF($W$6>G18,"good") -> FALSE
AO23: =IF($T$6>#REF!,"good") -> #REF!
AO24: =IF($T$6>D23,"good") -> FALSE

Sheet kotak
A1: Period Invested for | B1: ₹10000 Invested on | C1: Latest Value | D1: absolute returns | E1: Annualised Returns | F1: Category Avg | G1: Rank within Category | J1: here kh is in 500 or not | P1: here kh is in 500 or not
A2: 1 Week | B2: 45719 | C2: 10182.7 | D2: 0.0183 | E2: - | F2: 0.0151 | G2: 11293 | J2: =IF('kotak holdings'!A2='nifty 500 co list'!J2:J501,TRUE,FALSE) -> FALSE | P2: =IF('kotak holdings'!G2='nifty 500 co list'!P2:P501,TRUE,FALSE) -> FALSE
A3: 1 Month | B3: 45698 | C3: 9226.4 | D3: -0.0774 | E3: - | F3: -0.0663 | G3: 28/30 | J3: =IF('kotak holdings'!A3='nifty 500 co list'!J3:J502,TRUE,FALSE) -> FALSE | P3: =IF('kotak holdings'!G3='nifty 500 co list'!P3:P502,TRUE,FALSE) -> FALSE
A4: 3 Month | B4: 45636 | C4: 8135.8 | D4: -0.1864 | E4: - | F4: -0.1761 | G4: 25/30 | J4: =IF('kotak holdings'!A4='nifty 500 co list'!J4:J503,TRUE,FALSE) -> FALSE | P4: =IF('kotak holdings'!G4='nifty 500 co list'!P4:P503,TRUE,FALSE) -> FALSE
A5: 6 Month | B5: 45545 | C5: 8348.8 | D5: -0.1651 | E5: - | F5: -0.1711 | G5: 14/30 | J5: =IF('kotak holdings'!A5='nifty 500 co list'!J5:J504,TRUE,FALSE) -> FALSE | P5: =IF('kotak holdings'!G5='nifty 500 co list'!P5:P504,TRUE,FALSE) -> FALSE
A6: YTD | B6: 45658 | C6: 8287.6 | D6: -0.1712 | E6: - | F6: -0.1532 | G6: 26/30 | J6: =IF('kotak holdings'!A6='nifty 500 co list'!J6:J505,TRUE,FALSE) -> FALSE | P6: =IF('kotak holdings'!G6='nifty 500 co list'!P6:P505,TRUE,FALSE) -> FALSE
A7: 1 Year | B7: 45358 | C7: 10829.9 | D7: 0.083 | E7: 0.0823 | F7: 0.0369 | G7: 11079 | J7: =IF('kotak holdings'!A7='nifty 500 co list'!J7:J506,TRUE,FALSE) -> FALSE | P7: =IF('kotak holdings'!G7='nifty 500 co list'!P7:P506,TRUE,FALSE) -> FALSE
A8: 2 Year | B8: 44995 | C8: 14729.6 | D8: 0.473 | E8: 0.2133 | F8: 0.2362 | G8: 22/30 | J8: =IF('kotak holdings'!A8='nifty 500 co list'!J8:J507,TRUE,FALSE) -> FALSE | P8: =IF('kotak holdings'!G8='nifty 500 co list'!P8:P507,TRUE,FALSE) -> FALSE
A9: 3 Year | B9: 44630 | C9: 16441.2 | D9: 0.6441 | E9: 0.1801 | F9: 0.1805 | G9: 46357 | J9: =IF('kotak holdings'!A9='nifty 500 co list'!J9:J508,TRUE,FALSE) -> FALSE | P9: =IF('kotak holdings'!G9='nifty 500 co list'!P9:P508,TRUE,FALSE) -> FALSE
A10: 5 Year | B10: 43899 | C10: 28750.5 | D10: 1.875 | E10: 0.2349 | F10: 0.2312 | G10: 45597 | P10: =IF('kotak holdings'!G10='nifty 500 co list'!P10:P509,TRUE,FALSE) -> FALSE
A11: 10 Year | B11: 42073 | C11: 42845.5 | D11: 3.2846 | E11: 0.1565 | F11: 0.1415 | G11: 44317 | P11: =IF('kotak holdings'!G11='nifty 500 co list'!P11:P510,TRUE,FALSE) -> FALSE
A12: Since Inception | B12: 39171 | C12: 111664 | D12: 10.1664 | E12: 0.1438 | F12: 0.1754 | G12: 25/30 | P12: =IF('kotak holdings'!G12='nifty 500 co list'!P12:P511,TRUE,FALSE) -> FALSE
P13: =IF('kotak holdings'!G13='nifty 500 co list'!P13:P512,TRUE,FALSE) -> FALSE
P14: =IF('kotak holdings'!G14='nifty 500 co list'!P14:P513,TRUE,FALSE) -> FALSE
P15: =IF('kotak holdings'!G15='nifty 500 co list'!P15:P514,TRUE,FALSE) -> FALSE
B16: Period Invested for | C16: 1 Week | D16: 1 Month | E16: 3 Month | F16: 6 Month | G16: YTD | H16: 1 Year | I16: 2 Year | J16: 3 Year | K16: 5 Year | L16: 10 Year | M16: Since Inception | P16: =IF('kotak holdings'!G16='nifty 500 co list'!P16:P515,TRUE,FALSE) -> FALSE
B17: absolute returns | C17: 0.0183 | D17: -0.0774 | E17: -0.1864 | F17: -0.1651 | G17: -0.1712 | H17: 0.083 | I17: 0.473 | J17: 0.6441 | K17: 1.875 | L17: 3.2846 | M17: 10.1664 | P17: =IF('kotak holdings'!G17='nifty 500 co list'!P17:P516,TRUE,FALSE) -> FALSE
P18: =IF('kotak holdings'!G18='nifty 500 co list'!P18:P517,TRUE,FALSE) -> FALSE
P19: =IF('kotak holdings'!G19='nifty 500 co list'!P19:P518,TRUE,FALSE) -> FALSE
P20: =IF('kotak holdings'!G20='nifty 500 co list'!P20:P519,TRUE,FALSE) -> FALSE
P21: =IF('kotak holdings'!G21='nifty 500 co list'!P21:P520,TRUE,FALSE) -> FALSE
P22: =IF('kotak holdings'!G22='nifty 500 co list'!P22:P521,TRUE,FALSE) -> FALSE
P23: =IF('kotak holdings'!G23='nifty 500 co list'!P23:P522,TRUE,FALSE) -> FALSE
P24: =IF('kotak holdings'!G24='nifty 500 co list'!P24:P523,TRUE,FALSE) -> FALSE
P25: =IF('kotak holdings'!G25='nifty 500 co list'!P25:P524,TRUE,FALSE) -> FALSE
P26: =IF('kotak holdings'!G26='nifty 500 co list'!P26:P525,TRUE,FALSE) -> FALSE
B27: Period Invested for | C27: 1 Year | D27: 3 Year | E27: 5 Year | P27: =IF('kotak holdings'!G27='nifty 500 co list'!P27:P526,TRUE,FALSE) -> FALSE
B28: kotak returns | C28: 0.0823 | D28: 0.1801 | E28: 0.2349 | P28: =IF('kotak holdings'!G28='nifty 500 co list'!P28:P527,TRUE,FALSE) -> FALSE
B29: Nifty 500 | C29: 7.32% | D29: 0.4312 | E29: 194.27% | P29: =IF('kotak holdings'!G29='nifty 500 co list'!P29:P528,TRUE,FALSE) -> FALSE
P30: =IF('kotak holdings'!G30='nifty 500 co list'!P30:P529,TRUE,FALSE) -> FALSE
P31: =IF('kotak holdings'!G31='nifty 500 co list'!P31:P530,TRUE,FALSE) -> FALSE
P32: =IF('kotak holdings'!G32='nifty 500 co list'!P32:P531,TRUE,FALSE) -> FALSE
P33: =IF('kotak holdings'!G33='nifty 500 co list'!P33:P532,TRUE,FALSE) -> FALSE
P34: =IF('kotak holdings'!G34='nifty 500 co list'!P34:P533,TRUE,FALSE) -> FALSE
P35: =IF('kotak holdings'!G35='nifty 500 co list'!P35:P534,TRUE,FALSE) -> FALSE
P36: =IF('kotak holdings'!G36='nifty 500 co list'!P36:P535,TRUE,FALSE) -> FALSE
P37: =IF('kotak holdings'!G37='nifty 500 co list'!P37:P536,TRUE,FALSE) -> FALSE
P38: =IF('kotak holdings'!G38='nifty 500 co list'!P38:P537,TRUE,FALSE) -> FALSE
P39: =IF('kotak holdings'!G39='nifty 500 co list'!P39:P538,TRUE,FALSE) -> FALSE
P40: =IF('kotak holdings'!G40='nifty 500 co list'!P40:P539,TRUE,FALSE) -> FALSE
...

Sheet data valadiation
A1: Sector | C1: sectors | E1: Period Invested for
A2: Abrasives & bearings | C2: Coal | E2: =HYPERLINK("#'Kotak Holdings'!A1", " Kotak returns") -> Kotak returns
A3: Advertising & media agencies | C3: Mutual Fund | E3: =HYPERLINK("#'nippon holdings'!A1", "nippon returns") -> nippon returns
A4: Aerospace & defense | C4: Kotak returns | E4: =HYPERLINK("#'parag holdings'!A1","parag parik returns") -> parag parik returns
A5: Airline | C5: =IF(MATCH(C4,E2:E5,0)="Kotak Returns", (HYPERLINK("#'Kotak Holdings'!A1", "Go to Kotak")), IF(MATCH(C4,E2:E5,0)="Nippon Returns", (HYPERLINK("#'Nippon Holdings'!A1", "Go to Nippon")), IF(MATCH(C4,E2:E5,0)="Parag Returns",( HYPERLINK("#'Parag Holdings'!A1", "Go to Parag")), IF(MATCH(C4,E2:E5,0)="Quant Returns",( HYPERLINK("#'Quant Holdings'!A1", "Go to Quant")), "nil")))) -> nil | E5: =HYPERLINK("#'quant holdings'!A1", "quant returns") -> quant returns
A6: Amusement parks/ other recreation
A7: Animal feed
A8: Asset management company
A9: Auto ancillaries
A10: Auto components & equipments
A11: Auto dealer
A12: Breweries & distilleries
A13: Business process outsourcing (bpo)/ knowledge process outsourcing (kpo)
A14: Cables - electricals
A15: Cement & cement products
A16: Civil construction
A17: Coal
... A100: Tyres & allied

Sheet nippon
A1: Period Invested for | B1: ₹10000 Invested on | C1: Latest Value | D1: Absolute Returns | E1: Annualised Returns | F1: Category Avg | G1: Rank within Category
A2: 1 Week | B2: 45719 | C2: 10379.7 | D2: 0.038 | E2: - | F2: 0.0363 | G2: 14/32
A3: 1 Month | B3: 45698 | C3: 9278.9 | D3: -0.0721 | E3: - | F3: -0.0786 | G3: 12024
A4: 3 Month | B4: 45636 | C4: 7899.6 | D4: -0.21 | E4: - | F4: -0.2055 | G4: 17/31
A5: 6 Month | B5: 45545 | C5: 7970.7 | D5: -0.2029 | E5: - | F5: -0.194 | G5: 20/30
A6: YTD | B6: 45658 | C6: 8183.3 | D6: -0.1817 | E6: - | F6: -0.177 | G6: 11658
A7: 1 Year | B7: 45358 | C7: 10108 | D7: 0.0108 | E7: 0.0107 | F7: 0.017 | G7: 14/29
A8: 2 Year | B8: 44995 | C8: 15506 | D8: 0.5506 | E8: 0.2449 | F8: 0.2217 | G8: 46204
A9: 3 Year | B9: 44630 | C9: 17864.1 | D9: 0.7864 | E9: 0.2132 | F9: 0.1695 | G9: 45717
A10: 5 Year | B10: 43899 | C10: 39546.3 | D10: 2.9546 | E10: 0.3161 | F10: 0.268 | G10: 44986
A11: 10 Year | B11: 42073 | C11: 58163.2 | D11: 4.8163 | E11: 0.1923 | F11: 0.1499 | G11: 42005
A12: Since Inception | B12: 40437 | C12: 143909.7 | D12: 13.391 | E12: 0.202 | F12: 0.1585 | G12: 11232

Sheet parag parik
A1: Period Invested for | B1: ₹10000 Invested on | C1: Latest Value | D1: Absolute Returns | E1: Annualised Returns | F1: Category Avg | G1: Rank within Category
A2: 1 Week | B2: 45719 | C2: 10110.9 | D2: 0.0111 | E2: - | F2: 0.0152 | G2: 37/39
A3: 1 Month | B3: 45698 | C3: 9644.1 | D3: -0.0356 | E3: - | F3: -0.0595 | G3: 14305
A4: 3 Month | B4: 45636 | C4: 9404.7 | D4: -0.0595 | E4: - | F4: -0.147 | G4: 14246
A5: 6 Month | B5: 45545 | C5: 9752.8 | D5: -0.0247 | E5: - | F5: -0.1458 | G5: 14246
A6: YTD | B6: 45658 | C6: 9518.7 | D6: -0.0481 | E6: - | F6: -0.1181 | G6: 14246
A7: 1 Year | B7: 45358 | C7: 11028.3 | D7: 0.1028 | E7: 0.1028 | F7: 0.0101 | G7: 13912
A8: 2 Year | B8: 44995 | C8: 15723.5 | D8: 0.5723 | E8: 0.2547 | F8: 0.1857 | G8: 12479
A9: 3 Year | B9: 44630 | C9: 16471.9 | D9: 0.6472 | E9: 0.1814 | F9: 0.1335 | G9: 47209
A10: 5 Year | B10: 43899 | C10: 30870.6 | D10: 2.0871 | E10: 0.253 | F10: 0.1821 | G10: 44986
A11: 10 Year | B11: 42073 | C11: 46719.5 | D11: 3.6719 | E11: 0.1667 | F11: 0.1193 | G11: 43497
A12: Since Inception | B12: 41418 | C12: 77095.1 | D12: 6.7095 | E12: 0.1891 | F12: 0.1387 | G12: 14336

Sheet quant
B1: Period Invested for | C1: ₹10000 Invested on | D1: Latest Value | E1: Absolute Returns | F1: Annualised Returns | G1: Category Avg | H1: Rank within Category | K1: initial investment | L1: final value | M1: absolute return | N1: CAGR
A2: 7 | B2: 1 Week | C2: 45719 | D2: 10316.6 | E2: 0.0317 | F2: - | G2: 0.0151 | H2: 10959 | K2: 10000 | L2: =(1+E2/100)*10000 -> 10003.17 | M2: =((L2-10000)/10000)*100 -> 0.0317 | N2: =((L2/10000)^(1/A2)-1)*100 -> 0.0045279563
A3: 30 | B3: 1 Month | C3: 45698 | D3: 9413.4 | E3: -0.0587 | F3: - | G3: -0.0663 | H3: 11049 | K3: 10000 | L3: =(1+E3/100)*10000 -> 9994.13 | M3: =((L3-10000)/10000)*100 -> -0.0587 | N3: =((L3/10000)^(1/A3)-1)*100 -> -0.001957222
A4: 90 | B4: 3 Month | C4: 45636 | D4: 8479 | E4: -0.1521 | F4: - | G4: -0.1761 | H4: 11018 | K4: 10000 | L4: =(1+E4/100)*10000 -> 9984.79 | M4: =((L4-10000)/10000)*100 -> -0.1521 | N4: =((L4/10000)^(1/A4)-1)*100 -> -0.0016912722
A5: 180 | B5: 6 Month | C5: 45545 | D5: 7914 | E5: -0.2086 | F5: - | G5: -0.1711 | H5: 29/30 | K5: 10000 | L5: =(1+E5/100)*10000 -> 9979.14 | M5: =((L5-10000)/10000)*100 -> -0.2086 | N5: =((L5/10000)^(1/A5)-1)*100 -> -0.0011600926
B6: YTD | C6: 45658 | D6: 8657 | E6: -0.1343 | F6: - | G6: -0.1532 | H6: 11018 | K6: 10000 | L6: =(1+E6/100)*10000 -> 9986.57 | M6: =((L6-10000)/10000)*100 -> -0.1343 | N6: =((L6/10000)^(1/A6)-1)*100 -> #DIV/0!
A7: 365 | B7: 1 Year | C7: 45358 | D7: 9011.5 | E7: -0.0988 | F7: -0.0981 | G7: 0.0369 | H7: 30/30 | K7: 10000 | L7: =(1+E7/100)*10000 -> 9990.12 | M7: =((L7-10000)/10000)*100 -> -0.0988 | N7: =((L7/10000)^(1/A7)-1)*100 -> -0.00027081837
A8: 730 | B8: 2 Year | C8: 44995 | D8: 14756.6 | E8: 0.4757 | F8: 0.2144 | G8: 0.2362 | H8: 20/30 | K8: 10000 | L8: =(1+E8/100)*10000 -> 10047.57 | M8: =((L8-10000)/10000)*100 -> 0.4757 | N8: =((L8/10000)^(1/A8)-1)*100 -> 0.00065010091
A9: 1095 | B9: 3 Year | C9: 44630 | D9: 16833.5 | E9: 0.6834 | F9: 0.1894 | G9: 0.1805 | H9: 46327 | K9: 10000 | L9: =(1+E9/100)*10000 -> 10068.34 | M9: =((L9-10000)/10000)*100 -> 0.6834 | N9: =((L9/10000)^(1/A9)-1)*100 -> 0.00062198861
A10: 1825 | B10: 5 Year | C10: 43899 | D10: 36856.4 | E10: 2.6856 | F10: 0.2977 | G10: 0.2312 | H10: 45292 | K10: 10000 | L10: =(1+E10/100)*10000 -> 10268.56 | M10: =((L10-10000)/10000)*100 -> 2.6856 | N10: =((L10/10000)^(1/A10)-1)*100 -> 0.0014521589
A11: 3650 | B11: 10 Year | C11: 42073 | D11: 43161.6 | E11: 3.3162 | F11: 0.1573 | G11: 0.1415 | H11: 44287 | K11: 10000 | L11: =(1+E11/100)*10000 -> 10331.62 | M11: =((L11-10000)/10000)*100 -> 3.3162 | N11: =((L11/10000)^(1/A11)-1)*100 -> 0.00089381229
B12: Since Inception | C12: 36971 | D12: 192516.1 | E12: 18.2516 | F12: 0.1312 | G12: 0.1754 | H12: 27/30 | K12: 10000 | L12: =(1+E12/100)*10000 -> 11825.16 | M12: =((L12-10000)/10000)*100 -> 18.2516 | N12: =Q13=((L12/10000)^(1/A12)-1)*100 -> #DIV/0!

Sheet kotak holdings
A1: Stock Invested in | B1: Sector | C1: Value(Mn) | D1: % of Total Holdings | E1: 1M Change | F1: 1Y Highest Holding | G1: 1Y Lowest Holding | H1: Quantity | I1: 1M Change in Qty | J1: Column1
A2: Bharat Electronics Ltd. | B2: Aerospace & defense | C2: 9536.8 | D2: 0.0194 | E2: 0.0014 | F2: 3.62% (May 2024) | G2: 1.77% (Sep 2024) | H2: 3.26 Cr | I2: 0
A3: Schaeffler India Ltd. | B3: Auto components & equipments | C3: 9929.6 | D3: 0.0202 | E3: 0.0016 | F3: 3.54% (Jun 2024) | G3: 1.86% (Dec 2024) | H3: 28.98 L | I3: 0
A4: Exide Industries Ltd. | B4: Auto components & equipments | C4: 8396 | D4: 0.0171 | E4: -0.0005 | F4: 2.58% (Jun 2024) | G4: 1.71% (Jan 2025) | H4: 2.24 Cr | I4: 0
A5: Minda Industries Ltd. | B5: Auto components & equipments | C5: 5961.4 | D5: 0.0121 | E5: -0.0004 | F5: 1.27% (Nov 2024) | G5: 0.56% (Feb 2024) | H5: 63.04 L | I5: 0
A6: WABCO India Ltd. | B6: Auto components & equipments | C6: 3964.8 | D6: 0.0081 | E6: -0.0001 | F6: 1.02% (Oct 2024) | G6: 0.4% (Apr 2024) | H6: 3.59 L | I6: 0
A7: Sundram Fasteners Ltd. | B7: Auto components & equipments | C7: 2881.7 | D7: 0.0059 | E7: 0.0004 | F7: 0.76% (Jun 2024) | G7: 0.55% (Dec 2024) | H7: 27.60 L | I7: 0
A8: Motherson Sumi Systems Ltd. | B8: Auto components & equipments | C8: 1680.6 | D8: 0.0034 | E8: -0.0058 | F8: 2.42% (Jul 2024) | G8: 0.34% (Jan 2025) | H8: 1.19 Cr | I8: -1.94 Cr
A9: KEI Industries Ltd. | B9: Cables - electricals | C9: 6662.7 | D9: 0.0136 | E9: 0.0035 | F9: 1.36% (Jan 2025) | G9: 0% (Feb 2024) | H9: 16.56 L | I9: 4.45 L
A10: Polycab India Limited | B10: Cables - electricals | C10: 5956.3 | D10: 0.0121 | E10: -0.0014 | F10: 1.38% (Nov 2024) | G10: 0% (Feb 2024) | H10: 9.86 L | I10: 0
A11: Bharat Forge Ltd. | B11: Castings & forgings | C11: 7119.4 | D11: 0.0145 | E11: 0.0003 | F11: 2.81% (May 2024) | G11: 1.42% (Dec 2024) | H11: 58.16 L | I11: 0
A12: J.K. Cement Ltd. | B12: Cement & cement products | C12: 12322.6 | D12: 0.0251 | E12: 0.0029 | F12: 2.63% (Feb 2024) | G12: 1.99% (May 2024) | H12: 25.49 L | I12: -0.14 L
A13: The Ramco Cements Ltd. | B13: Cement & cement products | C13: 6344.4 | D13: 0.0129 | E13: 0.0003 | F13: 1.35% (Nov 2024) | G13: 0.93% (May 2024) | H13: 69.15 L | I13: 0
A14: Kajaria Ceramics Ltd. | B14: Ceramics | C14: 6397.7 | D14: 0.013 | E14: -0.0011 | F14: 1.89% (Jul 2024) | G14: 1.3% (Jan 2025) | H14: 64.53 L | I14: 0
A15: Techno Electric & Engineering Co. Ltd. | B15: Civil construction | C15: 2350.5 | D15: 0.0048 | E15: -0.0017 | F15: 0.65% (Dec 2024) | G15: 0% (Feb 2024) | H15: 21.81 L | I15: 0
A16: Mphasis Ltd. | B16: Computers - software & consulting | C16: 16719.2 | D16: 0.0341 | E16: 0.0028 | F16: 3.52% (Aug 2024) | G16: 1.04% (May 2024) | H16: 58.30 L | I16: 2.14 k
A17: Persistent Systems Ltd. | B17: Computers - software & consulting | C17: 12939.9 | D17: 0.0264 | E17: -0.0029 | F17: 4.16% (Oct 2024) | G17: 2.64% (Jan 2025) | H17: 21.45 L | I17: -2.62 L
A18: Wipro Ltd. | B18: Computers - software & consulting | C18: 11456.1 | D18: 0.0233 | E18: 0.0035 | F18: 2.33% (Jan 2025) | G18: 0% (Feb 2024) | H18: 3.67 Cr | I18: 18.50 L
A19: Birlasoft Ltd. | B19: Computers - software & consulting | C19: 9590.7 | D19: 0.0195 | E19: 0.0013 | F19: 1.95% (Jan 2025) | G19: 0% (Feb 2024) | H19: 1.79 Cr | I19: 6.92 L
A20: Tech Mahindra Ltd. | B20: Computers - software & consulting | C20: 3634.5 | D20: 0.0074 | E20: 0.0004 | F20: 0.88% (Oct 2024) | G20: 0.57% (May 2024) | H20: 21.71 L | I20: 0
A21: Dixon Technologies (India) Ltd. | B21: Consumer electronics | C21: 11293.7 | D21: 0.0239 | E21: -0.0025 | F21: 2.55% (Dec 2024) | G21: 1.58% (Feb 2024) | H21: 7.54 L | I21: 0
A22: Vishal Mega Mart Ltd. | B22: Diversified retail | C22: 907.7 | D22: 0.0018 | E22: 0.0001 | F22: 0.18% (Jan 2025) | G22: 0% (Feb 2024) | H22: 84.08 L | I22: 0
A23: Zomato Ltd. | B23: E-retail/ e-commerce | C23: 3140.1 | D23: 0.0064 | E23: -0.0011 | F23: 0.77% (Nov 2024) | G23: 0% (Feb 2024) | H23: 1.43 Cr | I23: 0
A24: Solar Industries India Ltd. | B24: Explosives | C24: 11273 | D24: 0.023 | E24: 0.0026 | F24: 4.56% (Mar 2024) | G24: 2.04% (Dec 2024) | H24: 11.06 L | I24: 0
A25: Coromandel International Ltd. | B25: Fertilizers | C25: 13690.3 | D25: 0.0279 | E25: 0.0011 | F25: 2.79% (Jan 2025) | G25: 2.05% (Feb 2024) | H25: 75.66 L | I25: 0
A26: Power Finance Corporation Ltd. | B26: Financial institution | C26: 10013.8 | D26: 0.0204 | E26: 0.0004 | F26: 2.71% (May 2024) | G26: 2% (Oct 2024) | H26: 2.37 Cr | I26: 0
A27: Rural Electrification Corporation Limited | B27: Financial institution | C27: 3230.6 | D27: 0.0066 | E27: -0.0002 | F27: 0.77% (Apr 2024) | G27: 0% (Feb 2024) | H27: 71.81 L | I27: 0
A28: Prudent Corporate Advisory Services Ltd. | B28: Financial products distributor | C28: 3811.5 | D28: 0.0078 | E28: -0.0019 | F28: 1.15% (Oct 2024) | G28: 0% (Feb 2024) | H28: 18.76 L | I28: 0
A29: Metro Brands Ltd. | B29: Footwear | C29: 7556.7 | D29: 0.0154 | E29: 0.0008 | F29: 1.54% (Jan 2025) | G29: 0.47% (Apr 2024) | H29: 63.78 L | I29: 0
A30: Page Industries Ltd. | B30: Garments & apparels | C30: 285.2 | D30: 0.0006 | E30: -0.0052 | F30: 0.58% (Dec 2024) | G30: 0.06% (Jan 2025) | H30: 6.38 k | I30: -0.58 L
A31: ICICI Lombard General Insurance Co Ltd. | B31: General insurance | C31: 7921.1 | D31: 0.0161 | E31: 0.0017 | F31: 1.66% (Aug 2024) | G31: 0% (Feb 2024) | H31: 42.62 L | I31: 0
A32: GE T&D India Ltd. | B32: Heavy electrical equipment | C32: 10400.4 | D32: 0.0212 | E32: 0.004 | F32: 2.12% (Jan 2025) | G32: 0% (Feb 2024) | H32: 58.18 L | I32: 14.23 L
A33: Thermax Ltd. | B33: Heavy electrical equipment | C33: 6486 | D33: 0.0132 | E33: 0.0004 | F33: 2.86% (Apr 2024) | G33: 1.28% (Dec 2024) | H33: 16.79 L | I33: 0
A34: Fortis Healthcare Ltd. | B34: Hospital | C34: 15828.5 | D34: 0.0322 | E34: -0.0013 | F34: 3.35% (Dec 2024) | G34: 0% (Feb 2024) | H34: 2.47 Cr | I34: 0
A35: Global Health Ltd. | B35: Hospital | C35: 7800.4 | D35: 0.0159 | E35: 0.0007 | F35: 1.59% (Jan 2025) | G35: 0% (Feb 2024) | H35: 75.03 L | I35: 0
A36: Max Healthcare Institute Ltd. | B36: Hospital | C36: 1157.6 | D36: 0.0024 | E36: 0.0024 | F36: 0.24% (Jan 2025) | G36: 0% (Feb 2024) | H36: 10.91 L | I36: 10.91 L
A37: Blue Star Ltd. | B37: Household appliances | C37: 9411.5 | D37: 0.0192 | E37: -0.0017 | F37: 2.09% (Dec 2024) | G37: 1.7% (Mar 2024) | H37: 51.78 L | I37: 0
A38: Voltas Limited | B38: Household appliances | C38: 6023 | D38: 0.0123 | E38: -0.0038 | F38: 1.67% (Sep 2024) | G38: 1.23% (Jan 2025) | H38: 47.77 L | I38: 0
A39: Amber Enterprises India Ltd. | B39: Household appliances | C39: 5902.9 | D39: 0.012 | E39: -0.0006 | F39: 1.26% (Dec 2024) | G39: 0.78% (May 2024) | H39: 9.08 L | I39: 0
A40: V-Guard Industries Ltd. | B40: Household appliances | C40: 3971.6 | D40: 0.0081 | E40: -0.0006 | F40: 0.99% (Jul 2024) | G40: 0.81% (Jan 2025) | H40: 1.09 Cr | I40: 0
...

Sheet nippon holdings
A1: Stock Invested in | B1: Sector | C1: Value(Mn) | D1: % of Total Holdings | E1: 1M Change | F1: 1Y Highest Holding | G1: 1Y Lowest Holding | H1: Quantity | I1: 1M Change in Qty
A2: Timken India Ltd. | B2: Abrasives & bearings | C2: 2930 | D2: 0.0058 | E2: 0 | F2: 0.87% (May 2024) | G2: 0.59% (Jan 2025) | H2: 11.84 L | I2: 0
A3: Grindwell Norton Ltd. | B3: Abrasives & bearings | C3: 1917.1 | D3: 0.0038 | E3: 0 | F3: 0.66% (May 2024) | G3: 0.41% (Dec 2024) | H3: 13.33 L | I3: 0
A4: Carborundum Universal Ltd. | B4: Abrasives & bearings | C4: 2715.8 | D4: 0.0053 | E4: 0 | F4: 1.01% (May 2024) | G4: 0.67% (Dec 2024) | H4: 32.66 L | I4: 0
A5: R K Swamy Ltd. | B5: Advertising & media agencies | C5: 450.9 | D5: 0.0009 | E5: 0 | F5: 0.13% (Mar 2024) | G5: 0% (Feb 2024) | H5: 21.15 L | I5: -0.41 k
A6: MTAR Technologies Ltd. | B6: Aerospace & defense | C6: 1192.8 | D6: 0.0023 | E6: 0 | F6: 0.33% (Feb 2024) | G6: 0.25% (Oct 2024) | H6: 9.26 L | I6: 0
A7: Mishra Dhatu Nigam Ltd. | B7: Aerospace & defense | C7: 364.4 | D7: 0.0007 | E7: 0 | F7: 0.13% (Feb 2024) | G7: 0.08% (Oct 2024) | H7: 14.99 L | I7: 0
A8: Hindustan Aeronautics Ltd. | B8: Aerospace & defense | C8: 2665 | D8: 0.0052 | E8: 0 | F8: 1.32% (Feb 2024) | G8: 0.46% (Aug 2024) | H8: 8.63 L | I8: 0
A9: Data Patterns India Ltd. | B9: Aerospace & defense | C9: 731.2 | D9: 0.0014 | E9: 0 | F9: 0.3% (Apr 2024) | G9: 0.19% (Sep 2024) | H9: 5.09 L | I9: 0
A10: Bharat Dynamics Ltd. | B10: Aerospace & defense | C10: 1489 | D10: 0.0029 | E10: 0 | F10: 0.46% (May 2024) | G10: 0.27% (Oct 2024) | H10: 15.26 L | I10: 0
A11: Astra Microwave Products Ltd. | B11: Aerospace & defense | C11: 1335.6 | D11: 0.0026 | E11: 0 | F11: 0.39% (May 2024) | G11: 0.27% (Dec 2024) | H11: 22.00 L | I11: 0
A12: InterGlobe Aviation Ltd. | B12: Airline | C12: 2205.3 | D12: 0.0043 | E12: 0 | F12: 1.28% (Apr 2024) | G12: 0% (Feb 2024) | H12: 4.93 L | I12: 4.71 L
A13: Wonderla Holidays Ltd. | B13: Amusement parks/ other recreation | C13: 400.1 | D13: 0.0008 | E13: 0 | F13: 0.09% (Nov 2024) | G13: 0% (Feb 2024) | H13: 6.26 L | I13: -0.11 L
A14: Godrej Agrovet Ltd. | B14: Animal feed | C14: 1602.6 | D14: 0.0032 | E14: 0 | F14: 0.32% (Jul 2024) | G14: 0.23% (May 2024) | H14: 22.41 L | I14: 0
A15: UTI Asset Management Co. Pvt. Ltd. | B15: Asset management company | C15: 1333.5 | D15: 0.0026 | E15: 0 | F15: 0.44% (Feb 2024) | G15: 0.26% (Jan 2025) | H15: 14.17 L | I15: 0
A16: Aditya Birla Sun Life AMC Ltd. | B16: Asset management company | C16: 1661.9 | D16: 0.0033 | E16: 0 | F16: 0.38% (Nov 2024) | G16: 0% (Feb 2024) | H16: 27.00 L | I16: 0
A17: Sharda Motor Industries Ltd. | B17: Auto ancillaries | C17: 651.6 | D17: 0.0013 | E17: 0 | F17: 0.18% (Aug 2024) | G17: 0% (Feb 2024) | H17: 4.15 L | I17: 0
A18: Tube Investments Of India Ltd. | B18: Auto components & equipments | C18: 6153.5 | D18: 0.0121 | E18: 0 | F18: 2.39% (Mar 2024) | G18: 1.44% (Dec 2024) | H18: 24.99 L | I18: 0
A19: Sundram Fasteners Ltd. | B19: Auto components & equipments | C19: 4391.9 | D19: 0.0086 | E19: 0 | F19: 0.86% (Jan 2025) | G19: 0% (Feb 2024) | H19: 47.03 L | I19: 0
A20: Subros Ltd. | B20: Auto components & equipments | C20: 552.6 | D20: 0.0011 | E20: 0 | F20: 0.13% (Aug 2024) | G20: 0.1% (Oct 2024) | H20: 9.68 L | I20: 0
A21: Schaeffler India Ltd. | B21: Auto components & equipments | C21: 1481.6 | D21: 0.0029 | E21: 0 | F21: 0.29% (Jan 2025) | G21: 0% (Feb 2024) | H21: 4.84 L | I21: 0
A22: Sansera Engineering Ltd. | B22: Auto components & equipments | C22: 863.8 | D22: 0.0017 | E22: 0 | F22: 0.2% (Nov 2024) | G22: 0% (Feb 2024) | H22: 7.72 L | I22: 0
A23: Sandhar Technologies Ltd. | B23: Auto components & equipments | C23: 881.3 | D23: 0.0017 | E23: 0 | F23: 0.29% (Feb 2024) | G23: 0.2% (Jan 2025) | H23: 25.62 L | I23: 0
A24: Rolex Rings Private Ltd. | B24: Auto components & equipments | C24: 279.1 | D24: 0.0005 | E24: 0 | F24: 0.09% (Jun 2024) | G24: 0.06% (Nov 2024) | H24: 1.97 L | I24: 0
A25: Motherson Sumi Systems Ltd. | B25: Auto components & equipments | C25: 2103.5 | D25: 0.0041 | E25: 0 | F25: 0.6% (Sep 2024) | G25: 0% (Feb 2024) | H25: 1.77 Cr | I25: 0
... A30: Divgi Torqtransfer Systems Private Ltd. | B30: Auto components & equipments | C30: 567.8 | D30: 0.0011 | E30: 0 | F30: 0.21% (Feb 2024) | G30: 0.11% (Dec 2024) | H30: 11.53 L | I30: 0
A31: Craftsman Automation Ltd. | B31: Auto components & equipments | C31: 1873 | D31: 0.0037 | E31: 0 | F31: 0.29% (Jan 2025) | G31: 0% (Feb 2024) | H31: 4.16 L | I31: 17.20 k
A32: CIE AUTOMOTIVE INDIA Ltd. | B32: Auto components & equipments | C32: 1867.8 | D32: 0.0037 | E32: 0 | F32: 0.72% (May 2024) | G32: 0% (Feb 2024) | H32: 49.67 L | I32: 0
A33: Automotive Axles Ltd. | B33: Auto components & equipments | C33: 1245.3 | D33: 0.0025 | E33: 0 | F33: 0.31% (Feb 2024) | G33: 0.22% (Nov 2024) | H33: 7.60 L | I33: 0
A34: Asahi India Glass Ltd. | B34: Auto components & equipments | C34: 1611.3 | D34: 0.0032 | E34: 0 | F34: 0.33% (Sep 2024) | G34: 0.27% (Aug 2024) | H34: 26.17 L | I34: 0
A35: Landmark Cars Ltd. | B35: Auto dealer | C35: 673.5 | D35: 0.0013 | E35: 0 | F35: 0.24% (Apr 2024) | G35: 0.13% (Jan 2025) | H35: 15.10 L | I35: 0
A36: Radico Khaitan Ltd. | B36: Breweries & distilleries | C36: 4620.6 | D36: 0.0091 | E36: 0 | F36: 0.94% (Dec 2024) | G36: 0.64% (Jul 2024) | H36: 22.29 L | I36: 0
A37: Allied Blenders and Distillers Ltd. | B37: Breweries & distilleries | C37: 1314.7 | D37: 0.0026 | E37: 0 | F37: 0.4% (Aug 2024) | G37: 0% (Feb 2024) | H37: 42.17 L | I37: 0
A38: eClerx Services Ltd. | B38: Business process outsourcing (bpo)/ knowledge process outsourcing (kpo) | C38: 4994.3 | D38: 0.0098 | E38: 0 | F38: 0.93% (Nov 2024) | G38: 0.65% (Jul 2024) | H38: 17.62 L | I38: 1.21 L
A39: Finolex Cables Ltd. | B39: Cables - electricals | C39: 2384 | D39: 0.0047 | E39: 0 | F39: 0.81% (May 2024) | G39: 0.51% (Jan 2025) | H39: 29.19 L | I39: 0
A40: Orient Cement Ltd. | B40: Cement & cement products | C40: 1120.6 | D40: 0.0022 | E40: 0 | F40: 0.34% (Jul 2024) | G40: 0.23% (May 2024) | H40: 34.00 L | I40: -0.19 Cr
A41: J K Lakshmi Cement Ltd. | B41: Cement & cement products | C41: 714 | D41: 0.0014 | E41: 0 | F41: 0.21% (Feb 2024) | G41: 0.13% (Nov 2024) | H41: 10.63 L | I41: 0
A42: Dalmia Bharat Ltd. | B42: Cement & cement products | C42: 462.8 | D42: 0.0009 | E42: 0.0009 | F42: 0% (Mar 2025) | G42: 0% (Mar 2025) | H42: 2.74 L | I42: 2.74 L
A43: Birla Corporation Ltd. | B43: Cement & cement products | C43: 2735.4 | D43: 0.0054 | E43: 0 | F43: 0.95% (Feb 2024) | G43: 0.54% (Oct 2024) | H43: 28.12 L | I43: 0
A44: Ambuja Cements Ltd. | B44: Cement & cement products | C44: 1255.4 | D44: 0.0025 | E44: 0 | F44: 0.36% (Feb 2024) | G44: 0.23% (Nov 2024) | H44: 27.00 L | I44: 0
...

Sheet parag holdings
B1: Sector | C1: Value(Mn) | D1: % of Total Holdings | E1: 1M Change | F1: 1Y Highest Holding | G1: 1Y Lowest Holding | H1: Quantity | I1: 1M Change in Qty
A2: HDFC Bank Ltd. | B2: Private sector bank | C2: 74169.4 | D2: 0.0843 | E2: 0 | F2: 8.57% (Jun 2024) | G2: 7.93% (Feb 2024) | H2: 4.28 Cr | I2: 0
A3: ICICI Bank Ltd. | B3: Private sector bank | C3: 42127.5 | D3: 0.0479 | E3: 0 | F3: 5.32% (Oct 2024) | G3: 4.89% (Jan 2025) | H3: 3.50 Cr | I3: 0
A4: Kotak Mahindra Bank Ltd. | B4: Private sector bank | C4: 37589.4 | D4: 0.0427 | E4: 0 | F4: 4.19% (Jan 2025) | G4: 2.23% (Feb 2024) | H4: 1.98 Cr | I4: 0
A5: Axis Bank Ltd. | B5: Private sector bank | C5: 27681.1 | D5: 0.0315 | E5: 0 | F5: 4.32% (Feb 2024) | G5: 3% (Jan 2025) | H5: 2.73 Cr | I5: 0
A6: Facebook | B6: Foreign equity | C6: 34556.4 | D6: 0.0393 | E6: 0 | F6: 4.08% (Feb 2024) | G6: 3.09% (Jul 2024) | H6: 5.91 L | I6: 0
A7: Alphabet Inc | B7: Foreign equity | C7: 28039.1 | D7: 0.0319 | E7: 0 | F7: 4.06% (May 2024) | G7: 3.17% (Nov 2024) | H7: 18.82 L | I7: 0
A8: Microsoft Corp | B8: Foreign equity | C8: 25461.8 | D8: 0.0289 | E8: 0 | F8: 4.27% (Feb 2024) | G8: 2.94% (Jan 2025) | H8: 7.33 L | I8: 0
A9: Amazon.com | B9: Foreign equity | C9: 25460.7 | D9: 0.0289 | E9: 0 | F9: 3.39% (Mar 2024) | G9: 2.59% (Sep 2024) | H9: 13.71 L | I9: 0
A10: Maruti Suzuki India Ltd. | B10: Passenger cars & utility vehicles | C10: 36053.5 | D10: 0.041 | E10: 0 | F10: 5.75% (Mar 2024) | G10: 3.77% (Dec 2024) | H10: 30.18 L | I10: 0
A11: Bajaj Holdings & Investment Ltd. | B11: Holding company | C11: 61563 | D11: 0.07 | E11: 0 | F11: 7.23% (Feb 2024) | G11: 6.03% (May 2024) | H11: 53.19 L | I11: 0
A12: Bajaj Finserv Ltd | B12: Holding company | C12: 114.2 | D12: 0.0001 | E12: 0 | F12: 0.01% (Jan 2025) | G12: 0% (Feb 2024) | H12: 61.00 k | I12: 0
A13: HCL Technologies Limited | B13: Computers - software & consulting | C13: 29464.4 | D13: 0.0335 | E13: 0 | F13: 5.28% (Feb 2024) | G13: 3.6% (Jan 2025) | H13: 1.87 Cr | I13: 0
... A23: Punjab National Bank | B23: Public sector bank | C23: 298.5 | D23: 0.0003 | E23: 0 | F23: 0.04% (Nov 2024) | G23: 0% (Feb 2024) | H23: 34.16 L | I23: 0
A24: Tata Communications Ltd. | B24: Telecom - cellular & fixed line services | C24: 1 | D24: 0 | E24: 0 | F24: 0% (Jan 2025) | G24: 0% (Feb 2024) | H24: 750 | I24: 0
A25: GMR Airports Infrastructure Ltd. | B25: Airport & airport services | C25: 115.7 | D25: 0.0001 | E25: 0 | F25: 0.02% (Nov 2024) | G25: 0% (Feb 2024) | H25: 16.65 L | I25: 0
A26: DLF Ltd. | B26: Residential, commercial projects | C26: 88.1 | D26: 0.0001 | E26: 0 | F26: 0.01% (Jul 2024) | G26: 0% (Feb 2024) | H26: 1.39 L | I26: 0
A27: Swaraj Engines Ltd. | B27: Compressors, pumps & diesel engines | C27: 123.7 | D27: 0.0001 | E27: 0 | F27: 0.02% (Jan 2025) | G27: 0.01% (Feb 2024) | H27: 47.29 k | I27: 0
A28: Tata Steel Ltd. | B28: Iron & steel products | C28: 13.6 | D28: 0 | E28: 0 | F28: 0% (Aug 2024) | G28: 0% (Feb 2024) | H28: 99.00 k | I28: 0
A29: Steel Authority Of India Ltd. | B29: Iron & steel products | C29: 16.4 | D29: 0 | E29: 0 | F29: 0% (Dec 2024) | G29: 0% (Feb 2024) | H29: 1.56 L | I29: 0
A30: Pi Industries Ltd. | B30: Pesticides & agrochemicals | C30: 15.8 | D30: 0 | E30: 0 | F30: 0% (Jul 2024) | G30: 0% (Feb 2024) | H30: 5.25 k | I30: 0
A31: United Spirits Ltd. | B31: Breweries & distilleries | C31: 1.8 | D31: 0 | E31: 0 | F31: 0% (Apr 2024) | G31: 0% (Nov 2024) | H31: 1.40 k | I31: 0
A32: Indus Towers Ltd. | B32: Telecom - infrastructure | C32: 9.4 | D32: 0 | E32: 0 | F32: 0% (Dec 2024) | G32: 0% (Feb 2024) | H32: 28.90 k | I32: 0
A33: Havells India Ltd. | B33: Consumer electronics | C33: 0.7 | D33: 0 | E33: 0 | F33: 0% (Jan 2025) | G33: 0% (Feb 2024) | H33: 500 | I33: 0
A34: Hindustan Copper Ltd. | B34: Copper | C34: 25.2 | D34: 0 | E34: 0 | F34: 0.02% (May 2024) | G34: 0% (Feb 2024) | H34: 1.25 L | I34: 0
A35: HDFC Life Insurance Company Ltd. | B35: Life insurance | C35: 12.1 | D35: 0 | E35: 0 | F35: 0% (Apr 2024) | G35: 0% (Nov 2024) | H35: 19.80 k | I35: 0
A36: InterGlobe Aviation Ltd. | B36: Airline | C36: 2 | D36: 0 | E36: 0 | F36: 0% (Jan 2025) | G36: 0% (Feb 2024) | H36: 450 | I36: 0
A37: Bharat Heavy Electricals Ltd. | B37: Heavy electrical equipment | C37: 40.9 | D37: 0 | E37: 0 | F37: 0.01% (Jul 2024) | G37: 0% (Feb 2024) | H37: 2.28 L | I37: 0
A38: Jindal Steel & Power Ltd. | B38: Iron & steel products | C38: 7.5 | D38: 0 | E38: 0 | F38: 0% (May 2024) | G38: 0% (Feb 2024) | H38: 8.75 k | I38: 0
A39: JSW Steel Ltd. | B39: Iron & steel products | C39: 2.6 | D39: 0 | E39: 0 | F39: 0% (Dec 2024) | G39: 0% (Feb 2024) | H39: 2.70 k | I39: 0
A40: ICRA Ltd. | B40: Ratings | C40: 1527.4 | D40: 0.0017 | E40: 0 | F40: 0.42% (Feb 2024) | G40: 0.21% (Jan 2025) | H40: 2.87 L | I40: -0.10 L
A41: Biocon Ltd. | B41: Pharmaceuticals | C41: 77.9 | D41: 0.0001 | E41: 0 | F41: 0.02% (May 2024) | G41: 0.01% (Nov 2024) | H41: 2.58 L | I41: -0.55 L
A42: Indusind Bank Ltd. | B42: Private sector bank | C42: 200 | D42: 0.0002 | E42: 0 | F42: 0.07% (Feb 2024) | G42: 0.03% (Nov 2024) | H42: 2.02 L | I42: -0.67 L
A43: Multi Commodity Exchange Of India Ltd. | B43: Exchange and data platform | C43: 3981.9 | D43: 0.0045 | E43: 0 | F43: 1.65% (Aug 2024) | G43: 0.56% (Jan 2025) | H43: 7.98 L | I43: -0.84 L
A44: Bharti Airtel Ltd. | B44: Telecom - cellular & fixed line services | C44: 478.8 | D44: 0.0005 | E44: 0 | F44: 0.04% (May 2024) | G44: 0% (Feb 2024) | H44: 3.05 L | I44: 1.06 L
A45: Sun Pharmaceutical Industries Ltd. | B45: Pharmaceuticals | C45: 194.6 | D45: 0.0002 | E45: 0.0002 | F45: 0% (Mar 2025) | G45: 0% (Mar 2025) | H45: 1.22 L | I45: 1.22 L
A46: Larsen & Toubro Ltd. | B46: Civil construction | C46: 484.5 | D46: 0.0006 | E46: 0 | F46: 0.01% (Jan 2025) | G46: 0% (Nov 2024) | H46: 1.53 L | I46: 1.22 L
A47: Bandhan Bank Ltd. | B47: Private sector bank | C47: 116.6 | D47: 0.0001 | E47: 0 | F47: 0.02% (Sep 2024) | G47: 0.01% (Nov 2024) | H47: 8.26 L | I47: 1.48 L
A48: Oil & Natural Gas Corporation Ltd. | B48: Oil exploration & production | C48: 241.5 | D48: 0.0003 | E48: 0 | F48: 0% (Nov 2024) | G48: 0% (Feb 2024) | H48: 10.72 L | I48: 10.43 L
A49: Hero Motocorp Ltd. | B49: 2/3 wheelers | C49: 48.6 | D49: 0.0001 | E49: 0.0001 | F49: 0% (Mar 2025) | G49: 0% (Mar 2025) | H49: 13.20 k | I49: 13.20 k
...

Sheet quant holdings
A1: Stock Invested in | B1: Sector | C1: Value(Mn) | D1: % of Total Holdings | E1: 1M Change | F1: 1Y Highest Holding | G1: 1Y Lowest Holding | H1: Quantity | I1: 1M Change in Qty
A2: Aurobindo Pharma Ltd. | B2: Pharmaceuticals | C2: 6995.1 | D2: 0.0813 | E2: -0.0083 | F2: 10% (Aug 2024) | G2: 6.94% (Mar 2024) | H2: 59.69 L | I2: 0
A3: Bharat Forge Ltd. | B3: Castings & forgings | C3: 2926.1 | D3: 0.034 | E3: -0.0009 | F3: 3.77% (Oct 2024) | G3: 0% (Feb 2024) | H3: 23.91 L | I3: 0
A4: Cochin Shipyard Ltd. | B4: Ship building & allied services | C4: 1348.7 | D4: 0.0157 | E4: 0.0005 | F4: 1.57% (Jan 2025) | G4: 0% (Feb 2024) | H4: 8.80 L | I4: 0
A5: Container Corporation Of India Ltd. | B5: Logistics solution provider | C5: 6382.8 | D5: 0.0741 | E5: 0.0016 | F5: 9.17% (Jul 2024) | G5: 1.44% (Feb 2024) | H5: 81.82 L | I5: 0
A6: CRISIL Ltd. | B6: Other financial services | C6: 1633.4 | D6: 0.019 | E6: -0.0035 | F6: 2.44% (Feb 2024) | G6: 1.42% (Jul 2024) | H6: 3.01 L | I6: 0
A7: GAIL (India) Ltd. : Futures Near | B7: Gas transmission/marketing | C7: 315.8 | D7: 0.0037 | E7: -0.0001 | F7: 0.38% (Dec 2024) | G7: 0% (Feb 2024) | H7: 17.74 L | I7: 0.17 Cr
A8: GlaxoSmithKline Pharmaceuticals Ltd. | B8: Pharmaceuticals | C8: 817.5 | D8: 0.0095 | E8: -0.0115 | F8: 2.52% (Oct 2024) | G8: 0.95% (Jan 2025) | H8: 4.13 L | I8: -4.16 L
A9: GMR Airports Infrastructure Ltd. | B9: Airport & airport services | C9: 1751.8 | D9: 0.0204 | E9: -0.0009 | F9: 3.41% (Feb 2024) | G9: 0% (Feb 2024) | H9: 2.41 Cr | I9: 0
A10: Housing & Urban Development Corporation Ltd. | B10: Financial institution | C10: 895.6 | D10: 0.0104 | E10: 0.0001 | F10: 1.04% (Jan 2025) | G10: 0% (Feb 2024) | H10: 38.99 L | I10: 0
A11: Indian Railway Catering and Tourism Corporation Ltd. | B11: Tour, travel related services | C11: 1360.9 | D11: 0.0158 | E11: 0.0012 | F11: 2.48% (Apr 2024) | G11: 0% (Feb 2024) | H11: 16.55 L | I11: 0
A12: Indus Towers Ltd. | B12: Telecom - infrastructure | C12: 1374.9 | D12: 0.016 | E12: 0.0008 | F12: 1.6% (Jan 2025) | G12: 0% (Feb 2024) | H12: 39.60 L | I12: 0
A13: Ipca Laboratories Ltd. | B13: Pharmaceuticals | C13: 1516.9 | D13: 0.0176 | E13: -0.0024 | F13: 2% (Dec 2024) | G13: 0% (Feb 2024) | H13: 10.51 L | I13: 0
A14: IRB Infrastructure Developers Ltd. | B14: Civil construction | C14: 7073 | D14: 0.0822 | E14: 0.0028 | F14: 8.82% (Jul 2024) | G14: 0% (Feb 2024) | H14: 12.34 Cr | I14: 0
A15: ITC Limited | B15: Diversified fmcg | C15: 4379.8 | D15: 0.0509 | E15: -0.0023 | F15: 5.35% (Oct 2024) | G15: 0% (Feb 2024) | H15: 97.87 L | I15: 0
A16: JSW Infrastructure Ltd. | B16: Engineering, designing, construction | C16: 924.4 | D16: 0.0107 | E16: -0.0013 | F16: 1.2% (Dec 2024) | G16: 0% (Feb 2024) | H16: 33.62 L | I16: 0
A17: Larsen & Toubro Ltd. : Futures Near | B17: Civil construction | C17: 845.1 | D17: 0.0098 | E17: 0.0002 | F17: 0.98% (Jan 2025) | G17: 0% (Feb 2024) | H17: 2.36 L | I17: 0.01 Cr
A18: Life Insurance Corporation Of India | B18: Life insurance | C18: 835.6 | D18: 0.0097 | E18: -0.0002 | F18: 1.12% (Aug 2024) | G18: 0% (Feb 2024) | H18: 9.88 L | I18: 0
A19: Linde India Ltd. | B19: Industrial gases | C19: 3000.7 | D19: 0.0349 | E19: 0.0026 | F19: 6.19% (Apr 2024) | G19: 3.23% (Dec 2024) | H19: 4.79 L | I19: 0
A20: Lloyds Metals And Energy Ltd. | B20: Sponge iron | C20: 4548.7 | D20: 0.0528 | E20: 0.0046 | F20: 5.28% (Jan 2025) | G20: 0% (Feb 2024) | H20: 36.71 L | I20: 1.90 L
A21: Marico Ltd. | B21: Personal care | C21: 5370 | D21: 0.0624 | E21: 0.0048 | F21: 6.24% (Jan 2025) | G21: 0% (Feb 2024) | H21: 80.07 L | I21: 0
A22: Mazagon Dock Shipbuilders Ltd. | B22: Ship building & allied services | C22: 2188.2 | D22: 0.0254 | E22: 0.0035 | F22: 2.54% (Jan 2025) | G22: 0% (Feb 2024) | H22: 8.76 L | I22: 0
A23: MRF Ltd. | B23: Tyres & rubber products | C23: 2147.4 | D23: 0.0249 | E23: -0.0029 | F23: 2.9% (Jul 2024) | G23: 0% (Feb 2024) | H23: 18.90 k | I23: 0
A24: NMDC LTD | B24: Industrial minerals | C24: 1235.6 | D24: 0.0144 | E24: 0.0005 | F24: 5.37% (Feb 2024) | G24: 0% (Feb 2024) | H24: 1.87 Cr | I24: 0
A25: Oil India Ltd. | B25: Oil exploration & production | C25: 846.7 | D25: 0.0098 | E25: 0 | F25: 3.07% (Mar 2024) | G25: 0% (Feb 2024) | H25: 20.14 L | I25: 0
A26: Oil India Ltd. : Futures Near | B26: Oil exploration & production | C26: 1412.7 | D26: 0.0164 | E26: 0 | F26: 1.64% (Jan 2025) | G26: 0% (Feb 2024) | H26: 33.46 L | I26: 0.32 Cr
A27: Reliance Industries Ltd. | B27: Refineries & marketing | C27: 8250.6 | D27: 0.0958 | E27: 0.0066 | F27: 10.52% (Jun 2024) | G27: 8.92% (Dec 2024) | H27: 65.22 L | I27: 0
A28: Steel Authority Of India Ltd. | B28: Iron & steel products | C28: 4553.6 | D28: 0.0529 | E28: -0.001 | F28: 8.78% (Jul 2024) | G28: 3.35% (Feb 2024) | H28: 4.24 Cr | I28: 0
A29: Tata Communications Ltd. | B29: Telecom - cellular & fixed line services | C29: 4966.1 | D29: 0.0577 | E29: -0.0006 | F29: 5.97% (Nov 2024) | G29: 2.47% (Aug 2024) | H29: 30.41 L | I29: 0
A30: Tata Communications Ltd. : Futures Near | B30: Telecom - cellular & fixed line services | C30: 692.7 | D30: 0.008 | E30: -0.0002 | F30: 2.15% (Sep 2024) | G30: 0% (Feb 2024) | H30: 4.23 L | I30: 0.03 Cr
A31: Tata Power Co. Ltd. | B31: Integrated power utilities | C31: 1245.2 | D31: 0.0145 | E31: -0.0006 | F31: 2.03% (May 2024) | G31: 0.84% (Apr 2024) | H31: 34.16 L | I31: 0
A32: Aditya Birla Fashion and Retail Ltd. | B32: Speciality retail | C32: 757.1 | D32: 0.0088 | E32: 0.0088 | F32: 0.88% (Jan 2025) | G32: 0% (Feb 2024) | H32: 27.64 L | I32: 27.64 L
A33: ITC Hotels Ltd | B33: Hotels & resorts | C33: 159.5 | D33: 0.0019 | E33: 0.0019 | F33: 0.19% (Jan 2025) | G33: 0% (Feb 2024) | H33: 9.79 L | I33: 9.79 L
A34: Airport & airport services | C34: 1751.8 | D34: 0.0204 | E34: -0.0009
A35: Castings & forgings | C35: 2926.1 | D35: 0.034 | E35: -0.0009
A36: Cement & cement products | C36: 960.4 | D36: 0 | E36: -0.0108
A37: Civil construction | C37: 7918.1 | D37: 0.092 | E37: 0.003
A38: Diversified fmcg | C38: 4379.8 | D38: 0.0509 | E38: -0.0023
A39: Engineering, designing, construction | C39: 924.4 | D39: 0.0107 | E39: -0.0013
A40: Financial institution | C40: 895.6 | D40: 0.0104 | E40: 0.0001
...

Sheet finding common co
A1: NF500 | B1: KOTAK | C1: MATCH DATA | D1: NIPPON | E1: MATCH DATA | F1: PARAG PARIK HOLINGS | G1: MATCH DATA | H1: QUANT | I1: MATCH DATA | J1: common on 2 or more companies
A2: Aavas Financiers Ltd. | B2: Coromandel International Ltd. | C2: =IF(ISNUMBER(MATCH(B2, $A$2:$A$501, 0)), "Present", "Absent") -> Present | D2: Motherson Sumi Systems Ltd. | E2: =IF(ISNUMBER(MATCH(D2, $A$1:$A$501, 0)), "Present", "Absent") -> Absent | F2: GMR Airports Infrastructure Ltd. | G2: =IF(ISNUMBER(MATCH(F2, $A$2:$A$501, 0)), "Present", "Absent") -> Absent | H2: Oil India Ltd. | I2: =IF(ISNUMBER(MATCH(H2, $A$2:$A$501, 0)), "Present","Absent") -> Present | J2: =IF( (COUNTIF($A$2:$A$501, $B$2:$B$67) > 0) + (COUNTIF($D$2:$D$234, $B$2:$B$67) > 0) + (COUNTIF($F$2:$F$204, $B$2:$B$67) > 0) + (COUNTIF($H$2:$H$33, $B$2:$B$67) > 0) >= 2, "Present", "Absent" ) -> Absent
A3: Adani Energy Solutions Ltd. | B3: Dixon Technologies (India) Ltd. | C3: =IF(ISNUMBER(MATCH(B3, $A$2:$A$501, 0)), "Present", "Absent") -> Present | D3: Schaeffler India Ltd. | E3: =IF(ISNUMBER(MATCH(D3, $A$1:$A$501, 0)), "Present", "Absent") -> Present | F3: ITC Hotels Ltd | G3: =IF(ISNUMBER(MATCH(F3, $A$2:$A$501, 0)), "Present", "Absent") -> Absent | H3: Marico Ltd. | I3: =IF(ISNUMBER(MATCH(H3, $A$2:$A$501, 0)), "Present","Absent") -> Present | J3: =IF( (COUNTIF($A$2:$A$501, $B$2:$B$67) > 0) + (COUNTIF($D$2:$D$234, $B$2:$B$67) > 0) + (COUNTIF($F$2:$F$204, $B$2:$B$67) > 0) + (COUNTIF($H$2:$H$33, $B$2:$B$67) > 0) >= 2, "Present", "Absent" ) -> Present
A4: Aditya Birla Capital Ltd. | B4: Mphasis Ltd. | C4: =IF(ISNUMBER(MATCH(B4, $A$2:$A$501, 0)), "Present", "Absent") -> Present | D4: Aditya Birla Sun Life AMC Ltd. | E4: =IF(ISNUMBER(MATCH(D4, $A$1:$A$501, 0)), "Present", "Absent") -> Present | F4: Indian Energy Exchange Ltd. | G4: =IF(ISNUMBER(MATCH(F4, $A$2:$A$501, 0)), "Present", "Absent") -> Present | H4: JSW Infrastructure Ltd. | I4: =IF(ISNUMBER(MATCH(H4, $A$2:$A$501, 0)), "Present","Absent") -> Present | J4: =IF( (COUNTIF($A$2:$A$501, $B$2:$B$67) > 0) + (COUNTIF($D$2:$D$234, $B$2:$B$67) > 0) + (COUNTIF($F$2:$F$204, $B$2:$B$67) > 0) + (COUNTIF($H$2:$H$33, $B$2:$B$67) > 0) >= 2, "Present", "Absent" ) -> Absent
A5: Aegis Logistics Ltd. | B5: The Ramco Cements Ltd. | C5: =IF(ISNUMBER(MATCH(B5, $A$2:$A$501, 0)), "Present", "Absent") -> Present | D5: Wonderla Holidays Ltd. | E5: =IF(ISNUMBER(MATCH(D5, $A$1:$A$501, 0)), "Present", "Absent") -> Absent | F5: HCL Technologies Limited | G5: =IF(ISNUMBER(MATCH(F5, $A$2:$A$501, 0)), "Present", "Absent") -> Absent | H5: Ipca Laboratories Ltd. | I5: =IF(ISNUMBER(MATCH(H5, $A$2:$A$501, 0)), "Present","Absent") -> Present | J5: =IF( (COUNTIF($A$2:$A$501, $B$2:$B$67) > 0) + (COUNTIF($D$2:$D$234, $B$2:$B$67) > 0) + (COUNTIF($F$2:$F$204, $B$2:$B$67) > 0) + (COUNTIF($H$2:$H$33, $B$2:$B$67) > 0) >= 2, "Present", "Absent" ) -> Absent
A6: Balrampur Chini Mills Ltd. | B6: Bharat Electronics Ltd. | C6: =IF(ISNUMBER(MATCH(B6, $A$2:$A$501, 0)), "Present", "Absent") -> Present | D6: Timken India Ltd. | E6: =IF(ISNUMBER(MATCH(D6, $A$1:$A$501, 0)), "Present", "Absent") -> Present | F6: HDFC Bank Ltd. | G6: =IF(ISNUMBER(MATCH(F6, $A$2:$A$501, 0)), "Present", "Absent") -> Present | H6: Aurobindo Pharma Ltd. | I6: =IF(ISNUMBER(MATCH(H6, $A$2:$A$501, 0)), "Present","Absent") -> Present | J6: =IF( (COUNTIF($A$2:$A$501, $B$2:$B$67) > 0) + (COUNTIF($D$2:$D$234, $B$2:$B$67) > 0) + (COUNTIF($F$2:$F$204, $B$2:$B$67) > 0) + (COUNTIF($H$2:$H$33, $B$2:$B$67) > 0) >= 2, "Present", "Absent" ) -> Present
A7: Bata India Ltd. | B7: Vishal Mega Mart Ltd. | C7: =IF(ISNUMBER(MATCH(B7, $A$2:$A$501, 0)), "Present", "Absent") -> Absent | D7: Sansera Engineering Ltd. | E7: =IF(ISNUMBER(MATCH(D7, $A$1:$A$501, 0)), "Present", "Absent") -> Absent | F7: Maharashtra Scooters Ltd. | G7: =IF(ISNUMBER(MATCH(F7, $A$2:$A$501, 0)), "Present", "Absent") -> Absent | H7: Mazagon Dock Shipbuilders Ltd. | I7: =IF(ISNUMBER(MATCH(H7, $A$2:$A$501, 0)), "Present","Absent") -> Present | J7: =IF( (COUNTIF($A$2:$A$501, $B$2:$B$67) > 0) + (COUNTIF($D$2:$D$234, $B$2:$B$67) > 0) + (COUNTIF($F$2:$F$204, $B$2:$B$67) > 0) + (COUNTIF($H$2:$H$33, $B$2:$B$67) > 0) >= 2, "Present", "Absent" ) -> Absent
